Workbook
Name Alpha: Parameters!$B$20
Name BC_HDR: Bond_Cashflows!$A$10
Name Beta: Parameters!$B$19
Name C_curr: Parameters!$B$13
Name C_min: Parameters!$B$14
Name CF_Gap_Total: Optimizer!$L$51
Name CF_Surplus: Optimizer!$K$31:$K$50
Name Con_Budget: Optimizer!$C$55
Name Con_Convex: Optimizer!$C$59
Name Con_DurHi: Optimizer!$C$57
Name Con_DurLo: Optimizer!$C$58
Name Con_HY: Optimizer!$C$60
Name Con_Issuer: Optimizer!$C$61
Name Con_Liquid: Optimizer!$C$62
Name Con_LongOnly: Optimizer!$C$63
Name Con_Solvency: Optimizer!$C$56
Name Conv_FABN: Parameters!$B$8
Name D_FABN: Parameters!$B$7
Name Delta: Parameters!$B$25
Name Eps_D: Parameters!$B$24
Name Eta: Parameters!$B$27
Name FABN_Rate: Parameters!$B$6
Name Gamma: Parameters!$B$18
Name Kappa: Parameters!$B$28
Name Lambda: Parameters!$B$21
Name NEV_Objective: Optimizer!$C$26
Name NOTIONAL_NR: Parameters!$B$5
Name Omega: Parameters!$B$26
Name RBC_bar: Parameters!$B$15
Name w_CS: Parameters!$B$34
Name w_MOM: Parameters!$B$33
Name w_MR: Parameters!$B$32
Name w_YC: Parameters!$B$31
Name Weights_h: Optimizer!$J$6:$J$11

Sheet Instructions
A1: FABN Bond Portfolio Optimizer – NEV / RBC ALM Framework
A2: OVERVIEW
A3: This workbook maximizes the Net Economic Value (NEV) of a FABN funding-agreement strategy.
A4: The optimizer allocates capital h_i ($) across bonds to:
A5: • Maximize spread income adjusted for market signals (Signal-enhanced Score)
A6: • Minimize regulatory capital costs (C-1 credit risk + C-3 ALM mismatch)
A7: • Penalize rebalancing frictions (transaction costs)
A8: • Minimize asset-liability cash flow mismatches over the 5-year horizon
A10: OBJECTIVE FUNCTION (green cell L39)
A11: max NEV = Σ Score_i · h_i − γ·(C1 + C3) − Σ τ_i·|h_i − h^curr| − λ·CFGap
A12: where Score_i = (y_i − r^FABN) + β · Signal_i
A13: and Signal_i = w_YC·YC_i + w_MR·MR_i + w_MOM·MOM_i + w_CS·CS_i
... A52: rows manually in Solver if needed for a strict per-issuer cap.

Sheet Parameters
A1: FABN + Bond Portfolio Optimizer – Model Parameters
A3: Parameter | B3: Value | C3: Description
A4: ── FABN / Liability ──
A5: FABN Notional H ($) | B5: 100000 | C5: Total capital allocated to bond portfolio
A6: FABN Crediting Rate r^FABN | B6: 0.05 | C6: Annual rate paid to FABN investors
A7: FABN Duration D^FABN (yrs) | B7: 5.5 | C7: Modified duration of liability
A8: FABN Convexity Conv^FABN | B8: 33 | C8: Liability convexity
A9: Payment Frequency | B9: Quarterly (every 3 mo.)
A10: Maturity (months) | B10: 60 | C10: 60 months = 5 years
A11: Simulation Horizon (mo) | B11: 60
A12: Start Date | B12: 46023
A13: Current Capital C^curr ($) | B13: 12000 | C13: Regulatory capital available today
A14: Minimum Capital C^min ($) | B14: 6000 | C14: RBC minimum capital threshold
A15: Minimum RBC Ratio RBC_bar | B15: 1 | C15: Solvency constraint floor
A17: ── NEV Penalty / Model Weights ──
A18: Gamma γ – Capital cost weight | B18: 0.12 | C18: Penalizes C1 + C3 regulatory capital cost
A19: Beta β – Signal impact weight | B19: 0.3 | C19: Scales market signal into Score_i
A20: Alpha α – C3 ALM scaling | B20: 0.2 | C20: Scales duration mismatch into C3 penalty
A21: Lambda λ – CF gap penalty | B21: 0.1 | C21: Penalizes asset–liability CF mismatch
A23: ── Constraint Limits ──
A24: Epsilon ε_D – Duration tolerance (yrs) | B24: 0.75 | C24: Max |D_avg − D^FABN| allowed (band: [4.75, 6.25] yrs)
A25: Delta δ – Convexity buffer (above L) | B25: 0.03 | C25: Conv_avg ≥ Conv^FABN × (1+δ) = 33.99
A26: Omega ω – Max HY allocation | B26: 0.2 | C26: Cap on high-yield bond allocation
A27: Eta η – Max issuer concentration | B27: 0.4 | C27: Cap on any single issuer's allocation
A28: Kappa κ – Min liquid allocation | B28: 0.35 | C28: Floor on liquid bond allocation
A30: ── Signal Weights (sum = 1.00) ──
A31: w_YC – Yield Curve weight | B31: 0.3 | C31: Bond cheap vs. interpolated Treasury curve
A32: w_MR – Mean Reversion weight | B32: 0.35 | C32: OAS wide vs. 12-month historical average
A33: w_MOM – Momentum weight | B33: 0.2 | C33: Recent total-return trend (z-score)
A34: w_CS – Capital Structure weight | B34: 0.15 | C34: Bond cheap vs. equity-implied credit spread

Sheet FABN_Liabilities
A1: FABN Liabilities – Monthly Cash Flow Schedule
A3: Month | B3: Date | C3: Quarterly Coupon ($) | D3: Principal ($) | E3: Total CF ($) | F3: Cumulative CF ($)
A4: 1 | B4: 46023 | C4: 0 | D4: 0 | E4: 0 | F4: 0
A5: 2 | B5: 46054 | C5: 0 | D5: 0 | E5: 0 | F5: 0
A6: 3 | B6: 46082 | C6: 1250 | D6: 0 | E6: 1250 | F6: 1250
A7: 4 | B7: 46113 | C7: 0 | D7: 0 | E7: 0 | F7: 1250
A8: 5 | B8: 46143 | C8: 0 | D8: 0 | E8: 0 | F8: 1250
A9: 6 | B9: 46174 | C9: 1250 | D9: 0 | E9: 1250 | F9: 2500
A10: 7 | B10: 46204 | C10: 0 | D10: 0 | E10: 0 | F10: 2500
A11: 8 | B11: 46235 | C11: 0 | D11: 0 | E11: 0 | F11: 2500
A12: 9 | B12: 46266 | C12: 1250 | D12: 0 | E12: 1250 | F12: 3750
A13: 10 | B13: 46296 | C13: 0 | D13: 0 | E13: 0 | F13: 3750
A14: 11 | B14: 46327 | C14: 0 | D14: 0 | E14: 0 | F14: 3750
A15: 12 | B15: 46357 | C15: 1250 | D15: 0 | E15: 1250 | F15: 5000
... A63: 60 | B63: 47818 | C63: 1250 | D63: 100000 | E63: 101250 | F63: 125000
A64: TOTAL | C64: =SUM(C4:C63) -> 25000 | D64: 100000 | E64: =SUM(E4:E63) -> 125000

Sheet Bond_Cashflows
A1: Bond + FABN Cash Flow Matrix – Per $1 Invested / Per $1 Notional
A2: Annual Coupon | C2: 0.052 | D2: 0.0505 | E2: 0.055 | F2: 0.0575 | G2: 0.062 | H2: 0.07 | I2: 0.05
A3: Freq (mo) | C3: 6 | D3: 3 | E3: 6 | F3: 6 | G3: 6 | H3: 6 | I3: 3
A4: 1st Pmt Mo | C4: 6 | D4: 3 | E4: 3 | F4: 9 | G4: 6 | H4: 6 | I4: 3
A5: Maturity Mo | C5: 60 | D5: 60 | E5: 60 | F5: 60 | G5: 54 | H5: 48 | I5: 60
A6: Rating | C6: AA | D6: AA | E6: A | F6: A | G6: BBB | H6: BB | I6: N/A
A7: Yield y_i | C7: 0.052 | D7: 0.0505 | E7: 0.055 | F7: 0.0575 | G7: 0.062 | H7: 0.07 | I7: 0.05
A8: C1 Factor θ | C8: 0.004 | D8: 0.004 | E8: 0.013 | F8: 0.013 | G8: 0.023 | H8: 0.045 | I8: —
A9: Txn Cost τ | C9: 0.001 | D9: 0.001 | E9: 0.0015 | F9: 0.002 | G9: 0.003 | H9: 0.005 | I9: —
A10: Month | B10: Date | C10: B01 AA-Fin 5.2% | D10: B02 AA-Govt 5.1% | E10: B03 A-Ind 5.5% | F10: B04 A-Engy 5.75% | G10: B05 BBB-Corp 6.2% | H10: B06 BB-HY 7.0% | I10: FABN (Liability) per $1
A11: 1 | B11: 46023
A12: 2 | B12: 46054
A13: 3 | B13: 46082 | D13: 0.012625 | E13: 0.0275 | I13: 0.0125
A14: 4 | B14: 46113
A15: 5 | B15: 46143
A16: 6 | B16: 46174 | C16: 0.026 | D16: 0.012625 | G16: 0.031 | H16: 0.035 | I16: 0.0125
A17: 7 | B17: 46204
A18: 8 | B18: 46235
A19: 9 | B19: 46266 | D19: 0.012625 | E19: 0.0275 | F19: 0.02875 | I19: 0.0125
A20: 10 | B20: 46296
A21: 11 | B21: 46327
A22: 12 | B22: 46357 | C22: 0.026 | D22: 0.012625 | G22: 0.031 | H22: 0.035 | I22: 0.0125
A23: 13 | B23: 46388
A24: 14 | B24: 46419
A25: 15 | B25: 46447 | D25: 0.012625 | E25: 0.0275 | F25: 0.02875 | I25: 0.0125
A26: 16 | B26: 46478
A27: 17 | B27: 46508
A28: 18 | B28: 46539 | C28: 0.026 | D28: 0.012625 | G28: 0.031 | H28: 0.035 | I28: 0.0125
A29: 19 | B29: 46569
A30: 20 | B30: 46600
A31: 21 | B31: 46631 | D31: 0.012625 | E31: 0.0275 | F31: 0.02875 | I31: 0.0125
A32: 22 | B32: 46661
A33: 23 | B33: 46692
A34: 24 | B34: 46722 | C34: 0.026 | D34: 0.012625 | G34: 0.031 | H34: 0.035 | I34: 0.0125
A35: 25 | B35: 46753
A36: 26 | B36: 46784
A37: 27 | B37: 46813 | D37: 0.012625 | E37: 0.0275 | F37: 0.02875 | I37: 0.0125
A38: 28 | B38: 46844
A39: 29 | B39: 46874
A40: 30 | B40: 46905 | C40: 0.026 | D40: 0.012625 | G40: 0.031 | H40: 0.035 | I40: 0.0125
...

Sheet Optimizer
A1: FABN Bond Portfolio Optimizer – NEV / RBC ALM Framework
A3: A. Bond Allocation | Signal Inputs (yellow = Solver / editable)
A4: Bond | B4: Rating | C4: Issuer | D4: Yield y_i | E4: Duration D_i | F4: Convexity Conv_i | G4: C1 Factor θ_i | H4: Txn Cost τ_i | I4: h_i^curr ($) | J4: h_i ($) ← PYTHON OPT | K4: YC Signal | L4: MR Signal | M4: MOM Signal | N4: CS Signal | O4: Composite Signal_i | P4: Score_i (y−r)+β·Sig | Q4: Liquid? | R4: HY?
D5: (%) | E5: (yrs) | H5: (%) | I5: ($) | J5: ($)
A6: B01 AA-Fin 5.2% | B6: AA | C6: Alpha | D6: 0.052 | E6: 5.5 | F6: 36.5 | G6: 0.004 | H6: 0.001 | I6: 16666.67 | J6: 40000 | K6: 0.12 | L6: 0.08 | M6: 0.06 | N6: 0.05 | O6: =w_YC*K6+w_MR*L6+w_MOM*M6+w_CS*N6 -> 0.0835 | P6: =D6-FABN_Rate+Beta*O6 -> 0.02705 | Q6: Y | R6: N
A7: B02 AA-Govt 5.1% | B7: AA | C7: Beta | D7: 0.0505 | E7: 5.8 | F7: 39 | G7: 0.004 | H7: 0.001 | I7: 16666.67 | J7: 18164.385 | K7: 0.08 | L7: 0.38 | M7: 0.05 | N7: 0.18 | O7: =w_YC*K7+w_MR*L7+w_MOM*M7+w_CS*N7 -> 0.194 | P7: =D7-FABN_Rate+Beta*O7 -> 0.0587 | Q7: Y | R7: N
A8: B03 A-Ind 5.5% | B8: A | C8: Gamma | D8: 0.055 | E8: 5.3 | F8: 35 | G8: 0.013 | H8: 0.0015 | I8: 16666.67 | J8: 19508.251 | K8: 0.2 | L8: 0.15 | M8: 0.18 | N8: 0.12 | O8: =w_YC*K8+w_MR*L8+w_MOM*M8+w_CS*N8 -> 0.1665 | P8: =D8-FABN_Rate+Beta*O8 -> 0.05495 | Q8: Y | R8: N
A9: B04 A-Engy 5.75% | B9: A | C9: Delta | D9: 0.0575 | E9: 5.5 | F9: 36 | G9: 0.013 | H9: 0.002 | I9: 16666.67 | J9: 22308.051 | K9: 0.3 | L9: 0.12 | M9: 0.28 | N9: 0.2 | O9: =w_YC*K9+w_MR*L9+w_MOM*M9+w_CS*N9 -> 0.218 | P9: =D9-FABN_Rate+Beta*O9 -> 0.0729 | Q9: N | R9: N
A10: B05 BBB-Corp 6.2% | B10: BBB | C10: Epsilon | D10: 0.062 | E10: 5 | F10: 34.5 | G10: 0.023 | H10: 0.003 | I10: 16666.67 | J10: 16.776584 | K10: 0.08 | L10: -0.05 | M10: 0.22 | N10: 0.08 | O10: =w_YC*K10+w_MR*L10+w_MOM*M10+w_CS*N10 -> 0.0625 | P10: =D10-FABN_Rate+Beta*O10 -> 0.03075 | Q10: N | R10: N
A11: B06 BB-HY 7.0% | B11: BB | C11: Zeta | D11: 0.07 | E11: 4.5 | F11: 33.5 | G11: 0.045 | H11: 0.005 | I11: 16666.67 | J11: 2.5366982 | K11: -0.15 | L11: -0.2 | M11: -0.15 | N11: -0.28 | O11: =w_YC*K11+w_MR*L11+w_MOM*M11+w_CS*N11 -> -0.187 | P11: =D11-FABN_Rate+Beta*O11 -> -0.0361 | Q11: N | R11: Y
A14: B. NEV Objective Breakdown (updates live as h_i or signals change)
A15: H (total capital) | C15: =SUM(J6:J11) -> 100000 | D15: Σ h_i — should equal NOTIONAL_NR
A16: Weighted-avg Duration D_avg | C16: =SUMPRODUCT(E6:E11,J6:J11)/SUM(J6:J11) -> 5.5153674 | D16: Σ D_i·h_i / H
A17: Weighted-avg Convexity | C17: =SUMPRODUCT(F6:F11,J6:J11)/SUM(J6:J11) -> 36.549534 | D17: Σ Conv_i·h_i / H
A18: ─────────────────────────────
A19: (1) Spread Income | C19: =SUMPRODUCT(P6:P11,J6:J11) -> 4846.909 | D19: Σ Score_i · h_i
A20: (2) C1 Cost = Σ θ_i · h_i | C20: =SUMPRODUCT(G6:G11,J6:J11) -> 776.76948 | D20: Regulatory C-1 capital charge
A21: (3) C3 Cost = α·|D_avg − D^FABN|·H | C21: =Alpha*ABS(SUMPRODUCT(E6:E11,J6:J11)/SUM(J6:J11)-D_FABN)*SUM(J6:J11) -> 307.34805 | D21: C-3 duration mismatch charge (non-linear)
A22: (4) Capital Cost = γ·(C1 + C3) | C22: =Gamma*(C20+C21) -> 130.0941 | D22: RBC capital penalty on portfolio
A23: (5) Transaction Costs = Σ τ_i·|h_i − h^curr| | C23: =SUMPRODUCT(H6:H11,ABS(J6:J11-I6:I11)) -> 173.64652 | D23: Rebalancing frictions (non-linear)
A24: (6) CF Gap = Σ_t |CF_A_t − CF_L_t| | C24: =SUM(L31:L50) -> 2097.2708 | D24: Sum of quarterly |asset CF − FABN CF| (→ see Section C)
A25: ─────────────────────────────
A26: NET ECONOMIC VALUE = (1) − (4) − (5) − λ·(6) | C26: =C19-C22-C23-Lambda*C24 -> 4333.4413 | D26: ← SOLVER OBJECTIVE (maximize this cell)
A28: C. Cash Flow Comparison – FABN Liability vs. Asset Portfolio (quarterly, $)
A29: Asset CF_t(h) = Σ CF_{i,t} · h_i | Liability CF_t = FABN quarterly payment | Surplus = Asset − Liability | |Gap| feeds into CF Gap penalty
A30: Month | B30: Date | C30: FABN CF $ [Liability] | D30: B01 AA-Fin 5.2% | E30: B02 AA-Govt 5.1% | F30: B03 A-Ind 5.5% | G30: B04 A-Engy 5.75% | H30: B05 BBB-Corp 6.2% | I30: B06 BB-HY 7.0% | J30: Total Asset CF $ | K30: Surplus $ | L30: |Asset−Liab| $
A31: 3 | B31: 46082 | C31: =FABN_Liabilities!E6 -> 1250 | D31: =Bond_Cashflows!C13*$J$6 -> 0 | E31: =Bond_Cashflows!D13*$J$7 -> 229.32536 | F31: =Bond_Cashflows!E13*$J$8 -> 536.47691 | G31: =Bond_Cashflows!F13*$J$9 -> 0 | H31: =Bond_Cashflows!G13*$J$10 -> 0 | I31: =Bond_Cashflows!H13*$J$11 -> 0 | J31: =SUM(D31:I31) -> 765.80226 | K31: =J31-C31 -> -484.19774 | L31: =ABS(J31-C31) -> 484.19774
A32: 6 | B32: 46174 | C32: =FABN_Liabilities!E9 -> 1250 | D32: =Bond_Cashflows!C16*$J$6 -> 1040 | E32: =Bond_Cashflows!D16*$J$7 -> 229.32536 | F32: =Bond_Cashflows!E16*$J$8 -> 0 | G32: =Bond_Cashflows!F16*$J$9 -> 0 | H32: =Bond_Cashflows!G16*$J$10 -> 0.52007411 | I32: =Bond_Cashflows!H16*$J$11 -> 0.088784438 | J32: =SUM(D32:I32) -> 1269.9342 | K32: =J32-C32 -> 19.934217 | L32: =ABS(J32-C32) -> 19.934217
A33: 9 | B33: 46266 | C33: =FABN_Liabilities!E12 -> 1250 | D33: =Bond_Cashflows!C19*$J$6 -> 0 | E33: =Bond_Cashflows!D19*$J$7 -> 229.32536 | F33: =Bond_Cashflows!E19*$J$8 -> 536.47691 | G33: =Bond_Cashflows!F19*$J$9 -> 641.35646 | H33: =Bond_Cashflows!G19*$J$10 -> 0 | I33: =Bond_Cashflows!H19*$J$11 -> 0 | J33: =SUM(D33:I33) -> 1407.1587 | K33: =J33-C33 -> 157.15872 | L33: =ABS(J33-C33) -> 157.15872
A34: 12 | B34: 46357 | C34: =FABN_Liabilities!E15 -> 1250 | D34: =Bond_Cashflows!C22*$J$6 -> 1040 | E34: =Bond_Cashflows!D22*$J$7 -> 229.32536 | F34: =Bond_Cashflows!E22*$J$8 -> 0 | G34: =Bond_Cashflows!F22*$J$9 -> 0 | H34: =Bond_Cashflows!G22*$J$10 -> 0.52007411 | I34: =Bond_Cashflows!H22*$J$11 -> 0.088784438 | J34: =SUM(D34:I34) -> 1269.9342 | K34: =J34-C34 -> 19.934217 | L34: =ABS(J34-C34) -> 19.934217
A35: 15 | B35: 46447 | C35: =FABN_Liabilities!E18 -> 1250 | D35: =Bond_Cashflows!C25*$J$6 -> 0 | E35: =Bond_Cashflows!D25*$J$7 -> 229.32536 | F35: =Bond_Cashflows!E25*$J$8 -> 536.47691 | G35: =Bond_Cashflows!F25*$J$9 -> 641.35646 | H35: =Bond_Cashflows!G25*$J$10 -> 0 | I35: =Bond_Cashflows!H25*$J$11 -> 0 | J35: =SUM(D35:I35) -> 1407.1587 | K35: =J35-C35 -> 157.15872 | L35: =ABS(J35-C35) -> 157.15872
A36: 18 | B36: 46539 | C36: =FABN_Liabilities!E21 -> 1250 | D36: =Bond_Cashflows!C28*$J$6 -> 1040 | E36: =Bond_Cashflows!D28*$J$7 -> 229.32536 | F36: =Bond_Cashflows!E28*$J$8 -> 0 | G36: =Bond_Cashflows!F28*$J$9 -> 0 | H36: =Bond_Cashflows!G28*$J$10 -> 0.52007411 | I36: =Bond_Cashflows!H28*$J$11 -> 0.088784438 | J36: =SUM(D36:I36) -> 1269.9342 | K36: =J36-C36 -> 19.934217 | L36: =ABS(J36-C36) -> 19.934217
A37: 21 | B37: 46631 | C37: =FABN_Liabilities!E24 -> 1250 | D37: =Bond_Cashflows!C31*$J$6 -> 0 | E37: =Bond_Cashflows!D31*$J$7 -> 229.32536 | F37: =Bond_Cashflows!E31*$J$8 -> 536.47691 | G37: =Bond_Cashflows!F31*$J$9 -> 641.35646 | H37: =Bond_Cashflows!G31*$J$10 -> 0 | I37: =Bond_Cashflows!H31*$J$11 -> 0 | J37: =SUM(D37:I37) -> 1407.1587 | K37: =J37-C37 -> 157.15872 | L37: =ABS(J37-C37) -> 157.15872
A38: 24 | B38: 46722 | C38: =FABN_Liabilities!E27 -> 1250 | D38: =Bond_Cashflows!C34*$J$6 -> 1040 | E38: =Bond_Cashflows!D34*$J$7 -> 229.32536 | F38: =Bond_Cashflows!E34*$J$8 -> 0 | G38: =Bond_Cashflows!F34*$J$9 -> 0 | H38: =Bond_Cashflows!G34*$J$10 -> 0.52007411 | I38: =Bond_Cashflows!H34*$J$11 -> 0.088784438 | J38: =SUM(D38:I38) -> 1269.9342 | K38: =J38-C38 -> 19.934217 | L38: =ABS(J38-C38) -> 19.934217
A39: 27 | B39: 46813 | C39: =FABN_Liabilities!E30 -> 1250 | D39: =Bond_Cashflows!C37*$J$6 -> 0 | E39: =Bond_Cashflows!D37*$J$7 -> 229.32536 | F39: =Bond_Cashflows!E37*$J$8 -> 536.47691 | G39: =Bond_Cashflows!F37*$J$9 -> 641.35646 | H39: =Bond_Cashflows!G37*$J$10 -> 0 | I39: =Bond_Cashflows!H37*$J$11 -> 0 | J39: =SUM(D39:I39) -> 1407.1587 | K39: =J39-C39 -> 157.15872 | L39: =ABS(J39-C39) -> 157.15872
A40: 30 | B40: 46905 | C40: =FABN_Liabilities!E33 -> 1250 | D40: =Bond_Cashflows!C40*$J$6 -> 1040 | E40: =Bond_Cashflows!D40*$J$7 -> 229.32536 | F40: =Bond_Cashflows!E40*$J$8 -> 0 | G40: =Bond_Cashflows!F40*$J$9 -> 0 | H40: =Bond_Cashflows!G40*$J$10 -> 0.52007411 | I40: =Bond_Cashflows!H40*$J$11 -> 0.088784438 | J40: =SUM(D40:I40) -> 1269.9342 | K40: =J40-C40 -> 19.934217 | L40: =ABS(J40-C40) -> 19.934217
A41: 33 | B41: 46997 | C41: =FABN_Liabilities!E36 -> 1250 | D41: =Bond_Cashflows!C43*$J$6 -> 0 | E41: =Bond_Cashflows!D43*$J$7 -> 229.32536 | F41: =Bond_Cashflows!E43*$J$8 -> 536.47691 | G41: =Bond_Cashflows!F43*$J$9 -> 641.35646 | H41: =Bond_Cashflows!G43*$J$10 -> 0 | I41: =Bond_Cashflows!H43*$J$11 -> 0 | J41: =SUM(D41:I41) -> 1407.1587 | K41: =J41-C41 -> 157.15872 | L41: =ABS(J41-C41) -> 157.15872
A42: 36 | B42: 47088 | C42: =FABN_Liabilities!E39 -> 1250 | D42: =Bond_Cashflows!C46*$J$6 -> 1040 | E42: =Bond_Cashflows!D46*$J$7 -> 229.32536 | F42: =Bond_Cashflows!E46*$J$8 -> 0 | G42: =Bond_Cashflows!F46*$J$9 -> 0 | H42: =Bond_Cashflows!G46*$J$10 -> 0.52007411 | I42: =Bond_Cashflows!H46*$J$11 -> 0.088784438 | J42: =SUM(D42:I42) -> 1269.9342 | K42: =J42-C42 -> 19.934217 | L42: =ABS(J42-C42) -> 19.934217
A43: 39 | B43: 47178 | C43: =FABN_Liabilities!E42 -> 1250 | D43: =Bond_Cashflows!C49*$J$6 -> 0 | E43: =Bond_Cashflows!D49*$J$7 -> 229.32536 | F43: =Bond_Cashflows!E49*$J$8 -> 536.47691 | G43: =Bond_Cashflows!F49*$J$9 -> 641.35646 | H43: =Bond_Cashflows!G49*$J$10 -> 0 | I43: =Bond_Cashflows!H49*$J$11 -> 0 | J43: =SUM(D43:I43) -> 1407.1587 | K43: =J43-C43 -> 157.15872 | L43: =ABS(J43-C43) -> 157.15872
A44: 42 | B44: 47270 | C44: =FABN_Liabilities!E45 -> 1250 | D44: =Bond_Cashflows!C52*$J$6 -> 1040 | E44: =Bond_Cashflows!D52*$J$7 -> 229.32536 | F44: =Bond_Cashflows!E52*$J$8 -> 0 | G44: =Bond_Cashflows!F52*$J$9 -> 0 | H44: =Bond_Cashflows!G52*$J$10 -> 0.52007411 | I44: =Bond_Cashflows!H52*$J$11 -> 0.088784438 | J44: =SUM(D44:I44) -> 1269.9342 | K44: =J44-C44 -> 19.934217 | L44: =ABS(J44-C44) -> 19.934217
...
